Workbook

Sheet S5_ReadMe
A1: Supplementary File S5 — Pilot Coding and Inter-Rater Reliability Procedures
A3: Item | B3: Procedure / rule
A4: Purpose | B4: Document the 25-study pilot-coding sample, independent reviewer forms, disagreement/refinement process, and inter-rater reliability calculations described in Section 3.8.
A5: Integrity rule | B5: Current workbook completion uses finalized S3 Reviewer-1 coding plus AI-assisted second-pass evidence verification for Reviewer-2 fields. These R2 values are NOT blind independent human coding and must not be reported as formal inter-rater-reliability results until human Reviewer 2 independently codes/signs off.
A6: Pilot sample | B6: Maximum-variation stratified purposive sample of 25 eligible studies. It stress-tests the codebook rather than estimating population proportions.
A7: Coverage | B7: All four engineering domains, four publication periods, multiple architectures, contribution types, evaluation methods, and low/high or non-applicable maturity cases.
A8: Screening reliability | B8: Title/abstract and full-text screening require separate reliability samples containing both Include and Exclude decisions. The 25 eligible pilot studies cannot be used to estimate binary screening kappa.
A9: Nominal variables | B9: Use raw agreement and Cohen’s kappa for binary/nominal primary decisions.
A10: Multi-label variables | B10: Use per-label binary Cohen’s kappa and Jaccard agreement for ED, RT, CT, LC, and EV.
A11: Ordinal variables | B11: Use weighted kappa for EM and reviewer-inferred TRL. For TRL ranges, assess lower and upper bounds separately; do not collapse to a midpoint.
A12: Weighting | B12: This supplement records both linear and quadratic weighted-kappa procedures. The manuscript must pre-specify which weighting is primary before final analysis.
A13: Targets | B13: Study-specific targets: ≥80% raw agreement and kappa ≥0.70 for core variables.
A14: Below-target response | B14: Inspect disagreement cases, refine definitions/decision rules, independently recode the pilot, recalculate agreement, and use third-reviewer adjudication only for unresolved cases.
A15: Reporting rule | B15: Report formal reliability by variable/facet only after independent human Reviewer-2 coding. Verification-only agreement values in this completed workbook are descriptive workflow checks, not manuscript IRR estimates.

Sheet Pilot_Sample_25
A1: Stratified Pilot-Coding Sample (25 Eligible Studies)
A3: Pilot ID | B3: Study ID | C3: Year | D3: Title | E3: Engineering stratum | F3: Period | G3: Architecture/context | H3: Contribution stratum | I3: Evaluation stratum | J3: Maturity coverage | K3: Selection rationale | L3: Coverage summary | M3: Domain | N3: Count | O3: Target | P3: Status
A4: P01 | B4: PS001 | C4: 2017 | D4: BLOCKBENCH: A Framework for Analyzing Private Blockchains | E4: ED1 | F4: 2016–2019 | G4: Private / permissioned | H4: Framework; benchmark | I4: Benchmark + controlled experiment | J4: Realistic experimental evidence | K4: Foundational performance benchmark. | M4: ED1 | N4: =COUNTIF(E4:E28,"ED1") -> 6 | O4: 6 | P4: =IF(N4=O4,"OK","CHECK") -> OK
A5: P02 | B5: PS004 | C5: 2020 | D5: Reputation-Based Coalition Formation for Secure Self-Organized and Scalable Sharding in IoT Blockchains With Mobile-Edge Computing | E5: ED1 | F5: 2020–2022 | G5: IoT / edge / sharding | H5: Architecture; algorithm | I5: Simulation | J5: Low–mid maturity | K5: Tests simulation and hybrid-context boundaries. | M5: ED2 | N5: =COUNTIF(E4:E28,"ED2") -> 6 | O5: 6 | P5: =IF(N5=O5,"OK","CHECK") -> OK
A6: P03 | B6: PS010 | C6: 2024 | D6: A Vehicular Trust Blockchain Framework With Scalable Byzantine Consensus | E6: ED1 | F6: 2023–2024 | G6: Vehicular / multi-shard | H6: Framework; protocol | I6: Controlled testbed | J6: Mid maturity | K6: Tests protocol/framework overlap and realistic testbed coding. | M6: ED3 | N6: =COUNTIF(E4:E28,"ED3") -> 6 | O6: 6 | P6: =IF(N6=O6,"OK","CHECK") -> OK
A7: P04 | B7: PS013 | C7: 2024 | D7: Lightweight, geo-scalable deterministic blockchain design for 5G networks sliced applications with hierarchical CFT/BFT consensus groups, IPFS and novel hardware design | E7: ED1 | F7: 2023–2024 | G7: 5G / IPFS hybrid | H7: Architecture; proof of concept | I7: 5G testbed + benchmark | J7: Mid maturity | K7: Complex hybrid architecture and lifecycle coding. | M7: ED4 | N7: =COUNTIF(E4:E28,"ED4") -> 7 | O7: 7 | P7: =IF(N7=O7,"OK","CHECK") -> OK
A8: P05 | B8: PS019 | C8: 2025 | D8: JUMBO: Fully Asynchronous BFT Consensus Made Truly Scalable | E8: ED1 | F8: 2025–2026 | G8: BFT blockchain consensus | H8: Protocol; algorithm | I8: Large-scale AWS experiments | J8: Realistic experimental evidence | K8: Recent formal + large-scale empirical protocol.
A9: P06 | B9: PS025 | C9: 2026 | D9: A Novel Dual-Layer Multi-Shard Blockchain Architecture for Vehicle Data Sharing | E9: ED1 | F9: 2025–2026 | G9: Vehicular / multi-shard | H9: Architecture; protocol | I9: Veins + MATLAB simulation | J9: Low–mid maturity | K9: Tests simulation versus readiness boundaries. | M9: Period | N9: Count | O9: Minimum | P9: Status
A10: P07 | B10: PS026 | C10: 2018 | D10: Atomic Cross-Chain Swaps | E10: ED2 | F10: 2016–2019 | G10: Public heterogeneous chains | H10: Protocol; formal model | I10: Formal/theoretical | J10: Conceptual / proof | K10: Low-maturity cross-chain formal protocol. | M10: 2016–2019 | N10: =COUNTIF(F4:F28,"2016–2019") -> 9 | O10: 3 | P10: =IF(N10>=O10,"OK","CHECK") -> OK
A11: P08 | B11: PS027 | C11: 2019 | D11: HyperService: Interoperability and Programmability Across Heterogeneous Blockchains | E11: ED2 | F11: 2016–2019 | G11: Heterogeneous cross-chain | H11: Framework; tool; protocol | I11: Prototype + experiment | J11: Realistic prototype | K11: Complex multi-contribution interoperability study. | M11: 2020–2022 | N11: =COUNTIF(F4:F28,"2020–2022") -> 5 | O11: 3 | P11: =IF(N11>=O11,"OK","CHECK") -> OK
A12: P09 | B12: PS028 | C12: 2019 | D12: XCLAIM: Trustless, Interoperable, Cryptocurrency-Backed Assets | E12: ED2 | F12: 2016–2019 | G12: Bitcoin–Ethereum | H12: Framework; protocol | I12: Implemented cross-chain evaluation | J12: Realistic prototype | K12: Formal security plus implemented cross-chain evidence. | M12: 2023–2024 | N12: =COUNTIF(F4:F28,"2023–2024") -> 6 | O12: 3 | P12: =IF(N12>=O12,"OK","CHECK") -> OK
A13: P10 | B13: PS030 | C13: 2021 | D13: Towards Cross-Blockchain Smart Contracts | E13: ED2 | F13: 2020–2022 | G13: Cross-chain smart contracts | H13: Framework; tool | I13: Live testnet proof of concept | J13: Laboratory / realistic | K13: Tests testnet-versus-operational boundary. | M13: 2025–2026 | N13: =COUNTIF(F4:F28,"2025–2026") -> 5 | O13: 3 | P13: =IF(N13>=O13,"OK","CHECK") -> OK
A14: P11 | B14: PS035 | C14: 2024 | D14: Automated Gateways: A Smart Contract-Powered Solution for Interoperability Across Blockchains | E14: ED2 | F14: 2023–2024 | G14: Fabric cross-network | H14: Framework; tool | I14: Production-mode cloud testbed | J14: Realistic experimental | K14: Enterprise-style interoperability context.
A15: P12 | B15: PS038 | C15: 2026 | D15: EquiLink Bridge: A Semi-Custodial Approach to Cross-Chain Transactions via TEE | E15: ED2 | F15: 2025–2026 | G15: Bridge + trusted execution | H15: Protocol; bridge; tool | I15: Cloud/SGX + attack tests | J15: Realistic experimental | K15: Security/privacy and cross-chain boundary case.
A16: P13 | B16: PS042 | C16: 2017 | D16: Blockchain-Oriented Software Engineering: Challenges and New Directions | E16: ED3 | F16: 2016–2019 | G16: Software repositories | H16: Empirical evidence; agenda | I16: Repository mining | J16: EM applicability stress | K16: Tests empirical evidence versus technology maturity.
A17: P14 | B17: PS043 | C17: 2019 | D17: Understanding the Motivations, Challenges and Needs of Blockchain Software Developers: A Survey | E17: ED3 | F17: 2016–2019 | G17: Developer practice | H17: Empirical evidence | I17: Developer survey | J17: EM applicability stress | K17: Tests practitioner evidence and maturity applicability.
A18: P15 | B18: PS044 | C18: 2020 | D18: ABCDE—Agile Block Chain DApp Engineering | E18: ED3 | F18: 2020–2022 | G18: DApp lifecycle | H18: Method; process | I18: Case + developer survey | J18: Low–mid maturity | K18: Tests lifecycle multi-label coding.
A19: P16 | B19: PS045 | C19: 2020 | D19: ChainIDE 2.0: Facilitating Smart Contract Development for Consortium Blockchain | E19: ED3 | F19: 2020–2022 | G19: Cloud IDE / multichain | H19: Tool | I19: Operational service statistics | J19: Operational stress case | K19: Tests operational evidence and TRL scope.
A20: P17 | B20: PS048 | C20: 2021 | D20: Integrated Model-Driven Engineering of Blockchain Applications for Business Processes and Asset Management | E20: ED3 | F20: 2020–2022 | G20: Enterprise process / assets | H20: Method; tool; framework | I20: Case studies + correctness/cost | J20: Realistic experimental | K20: Industry/government-derived cases.
A21: P18 | B21: PS059 | C21: 2025 | D21: Characterizing Smart Contract Evolution | E21: ED3 | F21: 2025–2026 | G21: Maintenance / evolution | H21: Empirical evidence; algorithm | I21: Repository/on-chain + survey | J21: EM applicability stress | K21: Tests LC7 and mixed empirical methods.
A22: P19 | B22: PS065 | C22: 2016 | D22: Making Smart Contracts Smarter | E22: ED4 | F22: 2016–2019 | G22: Ethereum assurance | H22: Tool; method | I22: Large-corpus security analysis | J22: Realistic experimental | K22: Foundational vulnerability analysis.
A23: P20 | B23: PS066 | C23: 2018 | D23: Securify: Practical Security Analysis of Smart Contracts | E23: ED4 | F23: 2016–2019 | G23: Ethereum assurance | H23: Tool; method | I23: Real-world contract analysis | J23: Practice-oriented | K23: Tests tool evaluation and readiness boundary.
A24: P21 | B24: PS067 | C24: 2018 | D24: ZEUS: Analyzing Safety of Smart Contracts | E24: ED4 | F24: 2016–2019 | G24: Ethereum / Fabric verification | H24: Framework; tool; method | I24: Large-corpus formal analysis | J24: Realistic experimental | K24: Cross-platform formal verification.
A25: P22 | B25: PS082 | C25: 2023 | D25: Correct-by-Design Interacting Smart Contracts and a Systematic Approach for Verifying ERC20 and ERC721 Contracts With VeriSolid | E25: ED4 | F25: 2023–2024 | G25: Ethereum verification | H25: Method; tool | I25: Formal verification + deployed contracts | J25: Realistic experimental | K25: Tests verification plus deployment workflow.
... A27: P24 | B27: PS089 | C27: 2024 | D27: SGDL: Smart Contract Vulnerability Generation via Deep Learning | E27: ED4 | F27: 2023–2024 | G27: Ethereum testing | H27: Tool; dataset; method | I27: Benchmark + comparison | J27: Realistic experimental | K27: Tests tool/dataset/method multi-label coding.
A28: P25 | B28: PS093 | C28: 2025 | D28: VULSEYE: Detect Smart Contract Vulnerabilities via Stateful Directed Graybox Fuzzing | E28: ED4 | F28: 2025–2026 | G28: Ethereum / DApps | H28: Tool; method | I28: Controlled + large real-world evaluation | J28: High realistic evidence | K28: Recent high-evidence fuzzing study. | L28: Pilot coding status | M28: R1 final S3 recode populated | N28: R2 verification populated | O28: Human independent R2 pending | P28: Formal IRR pending

Sheet Controlled_Vocab
A1: Controlled Codes — Use Supplementary File S3 for Definitions
A3: ED | B3: RT | C3: CT | D3: LC | E3: EV | F3: EM | G3: EM applicability | H3: TRL scope | I3: Binary | J3: Screening
A4: ED1 | B4: RT1 | C4: CT1 | D4: LC1 | E4: EV0 | F4: EM0 | G4: Applicable | H4: Component/Subsystem | I4: 0 | J4: Include
A5: ED2 | B5: RT2 | C5: CT2 | D5: LC2 | E5: EV1 | F5: EM1 | G5: Not applicable | H5: Integrated System | I5: 1 | J5: Exclude
A6: ED3 | B6: RT3 | C6: CT3 | D6: LC3 | E6: EV2 | F6: EM2 | G6: UNC | H6: UNC | J6: Not supplied
A7: ED4 | B7: RT4 | C7: CT4 | D7: LC4 | E7: EV3 | F7: EM3 | J7: Pending
B8: RT5 | C8: CT5 | D8: LC5 | E8: EV4 | F8: EM4
B9: RT6 | C9: CT6 | D9: LC6 | E9: EV5 | F9: EM5
C10: CT7 | D10: LC7 | E10: EV6 | F10: EM6
C11: CT8 | D11: LC8 | E11: EV7 | F11: EM7
C12: CT9 | E12: EV8
C13: CT10 | E13: EV9
C14: CT11 | E14: EV10
C15: CT12 | E15: EV11

Sheet Pilot_R1
A1: Pilot Coding — Reviewer 1 (Final S3 Recode)
A2: Values are populated from the finalized S3 Classification_Coding for the 25-study pilot sample.
A3: Pilot ID | B3: Study ID | C3: Title | D3: ED primary | E3: ED additional | F3: RT primary | G3: RT additional | H3: CT primary | I3: CT additional | J3: LC primary | K3: LC additional | L3: EV primary | M3: EV additional | N3: EM applicability | O3: EM code | P3: TRL lower | Q3: TRL upper | R3: TRL scope | S3: Ambiguity / notes | T3: Evidence page(s)
A4: P01 | B4: PS001 | C4: BLOCKBENCH: A Framework for Analyzing Private Blockchains | D4: ED1 | E4: — | F4: RT2 | G4: RT1 | H4: CT9 | I4: CT3 | J4: LC4 | K4: LC3 | L4: EV5 | M4: EV4 | N4: Applicable | O4: EM4 | P4: 4 | Q4: 5 | R4: Component/Subsystem | S4: Final S3 pilot recode using the current decision rules. | T4: pp. 1–2, Abstract/Introduction; pp. 4–7, Section 3; pp. 7–12, Sections 4–5; pp. 6–8, Sections 3.4–4; pp. 6–12, Sections 3.4–5; pp. 8–12, Sections 4–5; pp. 12–13, Discussion/Conclusion; pp. 1, 13, Abstract/References
A5: P02 | B5: PS004 | C5: Reputation-Based Coalition Formation for Secure Self-Organized and Scalable Sharding in IoT Blockchains With Mobile-Edge Computing | D5: ED1 | E5: — | F5: RT2 | G5: RT1 | H5: CT5 | I5: CT1; CT4 | J5: LC2 | K5: LC3; LC4 | L5: EV3 | M5: — | N5: Applicable | O5: EM2 | P5: 2 | Q5: 3 | R5: Component/Subsystem | S5: Final S3 pilot recode using the current decision rules. | T5: pp. 1–3, Abstract/Introduction; pp. 3–15, Sections III–V; pp. 15–19, Sections V–VI; pp. 15–16, Section VI-A; pp. 17–19, Section VI; pp. 15–19, Section VI; p. 1 and pp. 15–19
A6: P03 | B6: PS010 | C6: A Vehicular Trust Blockchain Framework With Scalable Byzantine Consensus | D6: ED1 | E6: — | F6: RT2 | G6: RT1 | H6: CT3 | I6: CT4; CT6 | J6: LC2 | K6: LC3; LC4 | L6: EV4 | M6: — | N6: Applicable | O6: EM4 | P6: 4 | Q6: 5 | R6: Integrated System | S6: Final S3 pilot recode using the current decision rules. | T6: pp. 1–2, Abstract/Introduction; pp. 2–10, Sections II–V; pp. 10–12, Section VI; pp. 10–11, Section VI; pp. 11–12, Sections VII–VIII; pp. 10–12
A7: P04 | B7: PS013 | C7: Lightweight, geo-scalable deterministic blockchain design for 5G networks sliced applications with hierarchical CFT/BFT consensus groups, IPFS and novel hardware design | D7: ED1 | E7: — | F7: RT2 | G7: RT1 | H7: CT4 | I7: CT6 | J7: LC2 | K7: LC3; LC4 | L7: EV8 | M7: EV4 | N7: Applicable | O7: EM5 | P7: 5 | Q7: 6 | R7: Integrated System | S7: Final S3 pilot recode using the current decision rules. | T7: pp. 1–2, Abstract/Introduction; pp. 2–14, Sections 1–4; pp. 14–20, Section 5; p. 14, Experimental setup; pp. 15–20, Section 5; p. 26, Section 7; pp. 14–20, 26
A8: P05 | B8: PS019 | C8: JUMBO: Fully Asynchronous BFT Consensus Made Truly Scalable | D8: ED1 | E8: — | F8: RT2 | G8: RT1 | H8: CT6 | I8: — | J8: LC2 | K8: LC3; LC4 | L8: EV4 | M8: EV5 | N8: Applicable | O8: EM4 | P8: 4 | Q8: 5 | R8: Component/Subsystem | S8: Final S3 pilot recode using the current decision rules. | T8: pp. 1–3, Introduction; pp. 3–15, protocol sections; pp. 15–17, Section VII; pp. 15–16, experimental setup; pp. 16–17, Section VII; pp. 15–17; artifact references and supplementary material
A9: P06 | B9: PS025 | C9: A Novel Dual-Layer Multi-Shard Blockchain Architecture for Vehicle Data Sharing | D9: ED1 | E9: — | F9: RT2 | G9: RT1 | H9: CT4 | I9: CT6 | J9: LC2 | K9: LC3; LC4 | L9: EV3 | M9: — | N9: Applicable | O9: EM2 | P9: 2 | Q9: 3 | R9: Integrated System | S9: Final S3 pilot recode using the current decision rules. | T9: pp. 1–3; pp. 2–13; pp. 13–17, Section VI; pp. 13–14; pp. 14–17; pp. 13–17
A10: P07 | B10: PS026 | C10: Atomic Cross-Chain Swaps | D10: ED2 | E10: — | F10: RT2 | G10: RT1 | H10: CT6 | I10: — | J10: LC2 | K10: LC3; LC4 | L10: EV1 | M10: — | N10: Applicable | O10: EM0 | P10: 1 | Q10: 2 | R10: Component/Subsystem | S10: Final S3 pilot recode using the current decision rules. | T10: pp. 1–3, Motivation/Contributions; pp. 3–8, model/protocol; pp. 3–9; pp. 5–9; pp. 2–10
A11: P08 | B11: PS027 | C11: HyperService: Interoperability and Programmability Across Heterogeneous Blockchains | D11: ED2 | E11: — | F11: RT2 | G11: RT1 | H11: CT3 | I11: CT4; CT6 | J11: LC2 | K11: LC3; LC4 | L11: EV4 | M11: EV5 | N11: Applicable | O11: EM4 | P11: 4 | Q11: 5 | R11: Integrated System | S11: Final S3 pilot recode using the current decision rules. | T11: pp. 1–2, Introduction; pp. 2–11; pp. 11–13, evaluation; p. 12, setup; pp. 12–13; pp. 11–13; artifact/reference section
A12: P09 | B12: PS028 | C12: XCLAIM: Trustless, Interoperable, Cryptocurrency-Backed Assets | D12: ED2 | E12: — | F12: RT2 | G12: RT1 | H12: CT6 | I12: CT1 | J12: LC2 | K12: LC3; LC4 | L12: EV4 | M12: EV5 | N12: Applicable | O12: EM4 | P12: 4 | Q12: 5 | R12: Component/Subsystem | S12: Final S3 pilot recode using the current decision rules. | T12: pp. 1–2, Introduction; pp. 2–11; pp. 11–12, Section VIII; p. 11, implementation/evaluation; p. 12; pp. 11–13; pp. 11–12
A13: P10 | B13: PS030 | C13: Towards Cross-Blockchain Smart Contracts | D13: ED2 | E13: — | F13: RT2 | G13: RT1 | H13: CT6 | I13: CT4 | J13: LC2 | K13: LC3; LC4 | L13: EV4 | M13: EV5 | N13: Applicable | O13: EM4 | P13: 4 | Q13: 5 | R13: Component/Subsystem | S13: Final S3 pilot recode using the current decision rules. | T13: pp. 2–3, Introduction; pp. 4–9; pp. 9–10, Section VI; p. 10, Section VI; pp. 10–11; pp. 9–11
A14: P11 | B14: PS035 | C14: Automated Gateways: A Smart Contract-Powered Solution for Interoperability Across Blockchains | D14: ED2 | E14: — | F14: RT2 | G14: RT1 | H14: CT3 | I14: CT6; CT7 | J14: LC2 | K14: LC3; LC4 | L14: EV5 | M14: EV4 | N14: Applicable | O14: EM4 | P14: 4 | Q14: 5 | R14: Integrated System | S14: Final S3 pilot recode using the current decision rules. | T14: pp. 1–2; pp. 3–6; pp. 6–7; p. 6, Section IV-A/B; pp. 6–8; p. 6, footnote 1
A15: P12 | B15: PS038 | C15: EquiLink Bridge: A Semi-Custodial Approach to Cross-Chain Transactions via TEE | D15: ED2 | E15: — | F15: RT2 | G15: RT1 | H15: CT4 | I15: CT6; CT7 | J15: LC2 | K15: LC3; LC4 | L15: EV4 | M15: EV5 | N15: Applicable | O15: EM4 | P15: 4 | Q15: 5 | R15: Integrated System | S15: Final S3 pilot recode using the current decision rules. | T15: pp. 1–2; pp. 4–9; pp. 9–13; pp. 10–12; pp. 9–12; pp. 10–13; p. 2, contributions/artifact
A16: P13 | B16: PS042 | C16: Blockchain-Oriented Software Engineering: Challenges and New Directions | D16: ED3 | E16: — | F16: RT3 | G16: — | H16: CT12 | I16: CT10 | J16: LC1 | K16: LC2; LC3; LC4 | L16: EV6 | M16: — | N16: Not applicable | O16: NA | P16: NA | Q16: NA | R16: NA | S16: Final S3 pilot recode using the current decision rules. EM is not applicable because the study does not evaluate a demonstrable technology/system/intervention. | T16: pp. 1–2; pp. 2–3; pp. 3–4; p. 3, Section IV
A17: P14 | B17: PS043 | C17: Understanding the Motivations, Challenges and Needs of Blockchain Software Developers: A Survey | D17: ED3 | E17: — | F17: RT3 | G17: — | H17: CT12 | I17: — | J17: LC1 | K17: LC3 | L17: EV7 | M17: — | N17: Not applicable | O17: NA | P17: NA | Q17: NA | R17: NA | S17: Final S3 pilot recode using the current decision rules. EM is not applicable because the study does not evaluate a demonstrable technology/system/intervention. | T17: pp. 1–7; methodology sections; methodology/demographics sections; methodology/results sections; results sections; discussion/conclusion; appendix/methodology
A18: P15 | B18: PS044 | C18: ABCDE—Agile Block Chain DApp Engineering | D18: ED3 | E18: — | F18: RT3 | G18: RT1 | H18: CT10 | I18: CT2 | J18: LC1 | K18: LC2; LC3; LC4; LC5 | L18: EV8 | M18: EV7; EV6 | N18: Applicable | O18: EM5 | P18: 5 | Q18: 6 | R18: Component/Subsystem | S18: Final S3 pilot recode using the current decision rules. | T18: pp. 1–2; pp. 2–10; pp. 4–15; pp. 10–15, Table 4/Section 5; p. 11, Table 4; pp. 10–16; pp. 4–16
A19: P16 | B19: PS045 | C19: ChainIDE 2.0: Facilitating Smart Contract Development for Consortium Blockchain | D19: ED3 | E19: — | F19: RT3 | G19: RT1 | H19: CT7 | I19: CT3 | J19: LC3 | K19: LC5 | L19: EV9 | M19: — | N19: Applicable | O19: EM6 | P19: 7 | Q19: 8 | R19: Integrated System | S19: Final S3 pilot recode using the current decision rules. | T19: pp. 1–2; pp. 2–4; pp. 3–5; pp. 4–5; pp. 4–5, Tables I–II; pp. 2–5
A20: P17 | B20: PS048 | C20: Integrated Model-Driven Engineering of Blockchain Applications for Business Processes and Asset Management | D20: ED3 | E20: — | F20: RT2 | G20: RT1 | H20: CT2 | I20: CT7 | J20: LC2 | K20: LC3; LC4; LC5 | L20: EV6 | M20: EV4 | N20: Applicable | O20: EM4 | P20: 4 | Q20: 5 | R20: Component/Subsystem | S20: Final S3 pilot recode using the current decision rules. | T20: pp. 1–3; pp. 3–16; pp. 17–24; pp. 17–23; pp. 20–24; pp. 23–24; pp. 15–24
A21: P18 | B21: PS059 | C21: Characterizing Smart Contract Evolution | D21: ED3 | E21: — | F21: RT3 | G21: RT2 | H21: CT12 | I21: CT5; CT7 | J21: LC7 | K21: LC4 | L21: EV5 | M21: EV7; EV6 | N21: Applicable | O21: EM4 | P21: 4 | Q21: 5 | R21: Component/Subsystem | S21: Final S3 pilot recode using the current decision rules. | T21: pp. 1–4; pp. 3–18; pp. 4–18; pp. 4–16; pp. 7–17; pp. 11–18; pp. 18–20; p. 4
A22: P19 | B22: PS065 | C22: Making Smart Contracts Smarter | D22: ED4 | E22: — | F22: RT2 | G22: RT1 | H22: CT7 | I22: CT2 | J22: LC4 | K22: — | L22: EV5 | M22: EV4 | N22: Applicable | O22: EM4 | P22: 4 | Q22: 5 | R22: Component/Subsystem | S22: Final S3 pilot recode using the current decision rules. | T22: Abstract; Sec. 1; Secs. 3–5; Sec. 6; Secs. 6–7; Abstract; Sec. 6; Secs. 1, 5–6
A23: P20 | B23: PS066 | C23: Securify: Practical Security Analysis of Smart Contracts | D23: ED4 | E23: — | F23: RT3 | G23: RT2; RT1 | H23: CT7 | I23: CT2 | J23: LC4 | K23: — | L23: EV9 | M23: EV5 | N23: Applicable | O23: EM6 | P23: 7 | Q23: 8 | R23: Component/Subsystem | S23: Final S3 pilot recode using the current decision rules. | T23: Abstract; Sec. 1; Secs. 3–6; Sec. 7; Secs. 1 and 7; Sec. 1; Abstract; Secs. 1 and 7
A24: P21 | B24: PS067 | C24: ZEUS: Analyzing Safety of Smart Contracts | D24: ED4 | E24: — | F24: RT2 | G24: RT1 | H24: CT7 | I24: CT2 | J24: LC4 | K24: — | L24: EV5 | M24: EV4 | N24: Applicable | O24: EM4 | P24: 4 | Q24: 5 | R24: Component/Subsystem | S24: Final S3 pilot recode using the current decision rules. | T24: Abstract; Sec. I; Secs. III–V; Sec. VI; Sec. VI-A; Abstract; Sec. VI; Secs. I and VI; full text
A25: P22 | B25: PS082 | C25: Correct-by-Design Interacting Smart Contracts and a Systematic Approach for Verifying ERC20 and ERC721 Contracts With VeriSolid | D25: ED4 | E25: ED3 | F25: RT2 | G25: RT1 | H25: CT2 | I25: CT7; CT10 | J25: LC4 | K25: LC2; LC3 | L25: EV5 | M25: EV4 | N25: Applicable | O25: EM4 | P25: 4 | Q25: 5 | R25: Component/Subsystem | S25: Final S3 pilot recode using the current decision rules. | T25: PDF pp. 1–2; PDF pp. 2–9; PDF pp. 2–10; PDF pp. 13–16; PDF pp. 13–17; PDF pp. 2 and 18
A26: P23 | B26: PS087 | C26: Smart Contract Vulnerability Detection Techniques for Hyperledger Fabric | D26: ED4 | E26: — | F26: RT2 | G26: RT1 | H26: CT7 | I26: — | J26: LC4 | K26: — | L26: EV2 | M26: — | N26: Applicable | O26: EM1 | P26: 2 | Q26: 3 | R26: Component/Subsystem | S26: Final S3 pilot recode using the current decision rules. | T26: PDF pp. 1–2; PDF pp. 2–5; PDF pp. 5–6; PDF p. 6; PDF pp. 6–7; PDF pp. 2–6
A27: P24 | B27: PS089 | C27: SGDL: Smart Contract Vulnerability Generation via Deep Learning | D27: ED4 | E27: — | F27: RT2 | G27: RT1 | H27: CT2 | I27: CT7 | J27: LC4 | K27: — | L27: EV5 | M27: EV4 | N27: Applicable | O27: EM4 | P27: 4 | Q27: 5 | R27: Component/Subsystem | S27: Final S3 pilot recode using the current decision rules. | T27: PDF pp. 1–2; PDF pp. 2–13; PDF pp. 7, 13–19; PDF pp. 7 and 13–19; PDF pp. 13–19; PDF pp. 14–20; PDF pp. 16–20; PDF pp. 13 and 22
A28: P25 | B28: PS093 | C28: VULSEYE: Detect Smart Contract Vulnerabilities via Stateful Directed Graybox Fuzzing | D28: ED4 | E28: — | F28: RT2 | G28: RT1 | H28: CT7 | I28: CT2 | J28: LC4 | K28: — | L28: EV5 | M28: EV4 | N28: Applicable | O28: EM4 | P28: 4 | Q28: 5 | R28: Component/Subsystem | S28: Final S3 pilot recode using the current decision rules. | T28: PDF pp. 1–4; PDF pp. 4–8; PDF pp. 6–9; PDF pp. 9–12; PDF pp. 11–13; PDF p. 2

Sheet Pilot_R2
A1: Pilot Coding — Reviewer 2 Evidence Verification (NOT Independent IRR Coding)
A2: Pilot ID | B2: Study ID | C2: Title | D2: ED primary | E2: ED additional | F2: RT primary | G2: RT additional | H2: CT primary | I2: CT additional | J2: LC primary | K2: LC additional | L2: EV primary | M2: EV additional | N2: EM applicability | O2: EM code | P2: TRL lower | Q2: TRL upper | R2: TRL scope | S2: Ambiguity / notes | T2: Evidence page(s)
A3: P01 | B3: PS001 | C3: BLOCKBENCH: A Framework for Analyzing Private Blockchains | D3: ED1 | E3: — | F3: RT2 | G3: RT1 | H3: CT9 | I3: CT3 | J3: LC4 | K3: LC3 | L3: EV5 | M3: EV4 | N3: Applicable | O3: EM4 | P3: 4 | Q3: 5 | R3: Component/Subsystem | S3: AI-assisted second-pass evidence verification reproduces the finalized S3 coding. This is not blind independent human Reviewer-2 coding; human R2 sign-off is pending. | T3: pp. 1–2, Abstract/Introduction; pp. 4–7, Section 3; pp. 7–12, Sections 4–5; pp. 6–8, Sections 3.4–4; pp. 6–12, Sections 3.4–5; pp. 8–12, Sections 4–5; pp. 12–13, Discussion/Conclusion; pp. 1, 13, Abstract/References
A4: P02 | B4: PS004 | C4: Reputation-Based Coalition Formation for Secure Self-Organized and Scalable Sharding in IoT Blockchains With Mobile-Edge Computing | D4: ED1 | E4: — | F4: RT2 | G4: RT1 | H4: CT5 | I4: CT1; CT4 | J4: LC2 | K4: LC3; LC4 | L4: EV3 | M4: — | N4: Applicable | O4: EM2 | P4: 2 | Q4: 3 | R4: Component/Subsystem | S4: AI-assisted second-pass evidence verification reproduces the finalized S3 coding. This is not blind independent human Reviewer-2 coding; human R2 sign-off is pending. | T4: pp. 1–3, Abstract/Introduction; pp. 3–15, Sections III–V; pp. 15–19, Sections V–VI; pp. 15–16, Section VI-A; pp. 17–19, Section VI; pp. 15–19, Section VI; p. 1 and pp. 15–19
A5: P03 | B5: PS010 | C5: A Vehicular Trust Blockchain Framework With Scalable Byzantine Consensus | D5: ED1 | E5: — | F5: RT2 | G5: RT1 | H5: CT3 | I5: CT4; CT6 | J5: LC2 | K5: LC3; LC4 | L5: EV4 | M5: — | N5: Applicable | O5: EM4 | P5: 4 | Q5: 5 | R5: Integrated System | S5: AI-assisted second-pass evidence verification reproduces the finalized S3 coding. This is not blind independent human Reviewer-2 coding; human R2 sign-off is pending. | T5: pp. 1–2, Abstract/Introduction; pp. 2–10, Sections II–V; pp. 10–12, Section VI; pp. 10–11, Section VI; pp. 11–12, Sections VII–VIII; pp. 10–12
A6: P04 | B6: PS013 | C6: Lightweight, geo-scalable deterministic blockchain design for 5G networks sliced applications with hierarchical CFT/BFT consensus groups, IPFS and novel hardware design | D6: ED1 | E6: — | F6: RT2 | G6: RT1 | H6: CT4 | I6: CT6 | J6: LC2 | K6: LC3; LC4 | L6: EV8 | M6: EV4 | N6: Applicable | O6: EM5 | P6: 5 | Q6: 6 | R6: Integrated System | S6: AI-assisted second-pass evidence verification reproduces the finalized S3 coding. This is not blind independent human Reviewer-2 coding; human R2 sign-off is pending. | T6: pp. 1–2, Abstract/Introduction; pp. 2–14, Sections 1–4; pp. 14–20, Section 5; p. 14, Experimental setup; pp. 15–20, Section 5; p. 26, Section 7; pp. 14–20, 26
A7: P05 | B7: PS019 | C7: JUMBO: Fully Asynchronous BFT Consensus Made Truly Scalable | D7: ED1 | E7: — | F7: RT2 | G7: RT1 | H7: CT6 | I7: — | J7: LC2 | K7: LC3; LC4 | L7: EV4 | M7: EV5 | N7: Applicable | O7: EM4 | P7: 4 | Q7: 5 | R7: Component/Subsystem | S7: AI-assisted second-pass evidence verification reproduces the finalized S3 coding. This is not blind independent human Reviewer-2 coding; human R2 sign-off is pending. | T7: pp. 1–3, Introduction; pp. 3–15, protocol sections; pp. 15–17, Section VII; pp. 15–16, experimental setup; pp. 16–17, Section VII; pp. 15–17; artifact references and supplementary material
A8: P06 | B8: PS025 | C8: A Novel Dual-Layer Multi-Shard Blockchain Architecture for Vehicle Data Sharing | D8: ED1 | E8: — | F8: RT2 | G8: RT1 | H8: CT4 | I8: CT6 | J8: LC2 | K8: LC3; LC4 | L8: EV3 | M8: — | N8: Applicable | O8: EM2 | P8: 2 | Q8: 3 | R8: Integrated System | S8: AI-assisted second-pass evidence verification reproduces the finalized S3 coding. This is not blind independent human Reviewer-2 coding; human R2 sign-off is pending. | T8: pp. 1–3; pp. 2–13; pp. 13–17, Section VI; pp. 13–14; pp. 14–17; pp. 13–17
A9: P07 | B9: PS026 | C9: Atomic Cross-Chain Swaps | D9: ED2 | E9: — | F9: RT2 | G9: RT1 | H9: CT6 | I9: — | J9: LC2 | K9: LC3; LC4 | L9: EV1 | M9: — | N9: Applicable | O9: EM0 | P9: 1 | Q9: 2 | R9: Component/Subsystem | S9: AI-assisted second-pass evidence verification reproduces the finalized S3 coding. This is not blind independent human Reviewer-2 coding; human R2 sign-off is pending. | T9: pp. 1–3, Motivation/Contributions; pp. 3–8, model/protocol; pp. 3–9; pp. 5–9; pp. 2–10
A10: P08 | B10: PS027 | C10: HyperService: Interoperability and Programmability Across Heterogeneous Blockchains | D10: ED2 | E10: — | F10: RT2 | G10: RT1 | H10: CT3 | I10: CT4; CT6 | J10: LC2 | K10: LC3; LC4 | L10: EV4 | M10: EV5 | N10: Applicable | O10: EM4 | P10: 4 | Q10: 5 | R10: Integrated System | S10: AI-assisted second-pass evidence verification reproduces the finalized S3 coding. This is not blind independent human Reviewer-2 coding; human R2 sign-off is pending. | T10: pp. 1–2, Introduction; pp. 2–11; pp. 11–13, evaluation; p. 12, setup; pp. 12–13; pp. 11–13; artifact/reference section
A11: P09 | B11: PS028 | C11: XCLAIM: Trustless, Interoperable, Cryptocurrency-Backed Assets | D11: ED2 | E11: — | F11: RT2 | G11: RT1 | H11: CT6 | I11: CT1 | J11: LC2 | K11: LC3; LC4 | L11: EV4 | M11: EV5 | N11: Applicable | O11: EM4 | P11: 4 | Q11: 5 | R11: Component/Subsystem | S11: AI-assisted second-pass evidence verification reproduces the finalized S3 coding. This is not blind independent human Reviewer-2 coding; human R2 sign-off is pending. | T11: pp. 1–2, Introduction; pp. 2–11; pp. 11–12, Section VIII; p. 11, implementation/evaluation; p. 12; pp. 11–13; pp. 11–12
A12: P10 | B12: PS030 | C12: Towards Cross-Blockchain Smart Contracts | D12: ED2 | E12: — | F12: RT2 | G12: RT1 | H12: CT6 | I12: CT4 | J12: LC2 | K12: LC3; LC4 | L12: EV4 | M12: EV5 | N12: Applicable | O12: EM4 | P12: 4 | Q12: 5 | R12: Component/Subsystem | S12: AI-assisted second-pass evidence verification reproduces the finalized S3 coding. This is not blind independent human Reviewer-2 coding; human R2 sign-off is pending. | T12: pp. 2–3, Introduction; pp. 4–9; pp. 9–10, Section VI; p. 10, Section VI; pp. 10–11; pp. 9–11
A13: P11 | B13: PS035 | C13: Automated Gateways: A Smart Contract-Powered Solution for Interoperability Across Blockchains | D13: ED2 | E13: — | F13: RT2 | G13: RT1 | H13: CT3 | I13: CT6; CT7 | J13: LC2 | K13: LC3; LC4 | L13: EV5 | M13: EV4 | N13: Applicable | O13: EM4 | P13: 4 | Q13: 5 | R13: Integrated System | S13: AI-assisted second-pass evidence verification reproduces the finalized S3 coding. This is not blind independent human Reviewer-2 coding; human R2 sign-off is pending. | T13: pp. 1–2; pp. 3–6; pp. 6–7; p. 6, Section IV-A/B; pp. 6–8; p. 6, footnote 1
A14: P12 | B14: PS038 | C14: EquiLink Bridge: A Semi-Custodial Approach to Cross-Chain Transactions via TEE | D14: ED2 | E14: — | F14: RT2 | G14: RT1 | H14: CT4 | I14: CT6; CT7 | J14: LC2 | K14: LC3; LC4 | L14: EV4 | M14: EV5 | N14: Applicable | O14: EM4 | P14: 4 | Q14: 5 | R14: Integrated System | S14: AI-assisted second-pass evidence verification reproduces the finalized S3 coding. This is not blind independent human Reviewer-2 coding; human R2 sign-off is pending. | T14: pp. 1–2; pp. 4–9; pp. 9–13; pp. 10–12; pp. 9–12; pp. 10–13; p. 2, contributions/artifact
A15: P13 | B15: PS042 | C15: Blockchain-Oriented Software Engineering: Challenges and New Directions | D15: ED3 | E15: — | F15: RT3 | G15: — | H15: CT12 | I15: CT10 | J15: LC1 | K15: LC2; LC3; LC4 | L15: EV6 | M15: — | N15: Not applicable | O15: NA | P15: NA | Q15: NA | R15: NA | S15: AI-assisted second-pass evidence verification reproduces the finalized S3 coding. This is not blind independent human Reviewer-2 coding; human R2 sign-off is pending. EM not-applicable status was also verified from the recorded evidence. | T15: pp. 1–2; pp. 2–3; pp. 3–4; p. 3, Section IV
A16: P14 | B16: PS043 | C16: Understanding the Motivations, Challenges and Needs of Blockchain Software Developers: A Survey | D16: ED3 | E16: — | F16: RT3 | G16: — | H16: CT12 | I16: — | J16: LC1 | K16: LC3 | L16: EV7 | M16: — | N16: Not applicable | O16: NA | P16: NA | Q16: NA | R16: NA | S16: AI-assisted second-pass evidence verification reproduces the finalized S3 coding. This is not blind independent human Reviewer-2 coding; human R2 sign-off is pending. EM not-applicable status was also verified from the recorded evidence. | T16: pp. 1–7; methodology sections; methodology/demographics sections; methodology/results sections; results sections; discussion/conclusion; appendix/methodology
A17: P15 | B17: PS044 | C17: ABCDE—Agile Block Chain DApp Engineering | D17: ED3 | E17: — | F17: RT3 | G17: RT1 | H17: CT10 | I17: CT2 | J17: LC1 | K17: LC2; LC3; LC4; LC5 | L17: EV8 | M17: EV7; EV6 | N17: Applicable | O17: EM5 | P17: 5 | Q17: 6 | R17: Component/Subsystem | S17: AI-assisted second-pass evidence verification reproduces the finalized S3 coding. This is not blind independent human Reviewer-2 coding; human R2 sign-off is pending. | T17: pp. 1–2; pp. 2–10; pp. 4–15; pp. 10–15, Table 4/Section 5; p. 11, Table 4; pp. 10–16; pp. 4–16
A18: P16 | B18: PS045 | C18: ChainIDE 2.0: Facilitating Smart Contract Development for Consortium Blockchain | D18: ED3 | E18: — | F18: RT3 | G18: RT1 | H18: CT7 | I18: CT3 | J18: LC3 | K18: LC5 | L18: EV9 | M18: — | N18: Applicable | O18: EM6 | P18: 7 | Q18: 8 | R18: Integrated System | S18: AI-assisted second-pass evidence verification reproduces the finalized S3 coding. This is not blind independent human Reviewer-2 coding; human R2 sign-off is pending. | T18: pp. 1–2; pp. 2–4; pp. 3–5; pp. 4–5; pp. 4–5, Tables I–II; pp. 2–5
A19: P17 | B19: PS048 | C19: Integrated Model-Driven Engineering of Blockchain Applications for Business Processes and Asset Management | D19: ED3 | E19: — | F19: RT2 | G19: RT1 | H19: CT2 | I19: CT7 | J19: LC2 | K19: LC3; LC4; LC5 | L19: EV6 | M19: EV4 | N19: Applicable | O19: EM4 | P19: 4 | Q19: 5 | R19: Component/Subsystem | S19: AI-assisted second-pass evidence verification reproduces the finalized S3 coding. This is not blind independent human Reviewer-2 coding; human R2 sign-off is pending. | T19: pp. 1–3; pp. 3–16; pp. 17–24; pp. 17–23; pp. 20–24; pp. 23–24; pp. 15–24
A20: P18 | B20: PS059 | C20: Characterizing Smart Contract Evolution | D20: ED3 | E20: — | F20: RT3 | G20: RT2 | H20: CT12 | I20: CT5; CT7 | J20: LC7 | K20: LC4 | L20: EV5 | M20: EV7; EV6 | N20: Applicable | O20: EM4 | P20: 4 | Q20: 5 | R20: Component/Subsystem | S20: AI-assisted second-pass evidence verification reproduces the finalized S3 coding. This is not blind independent human Reviewer-2 coding; human R2 sign-off is pending. | T20: pp. 1–4; pp. 3–18; pp. 4–18; pp. 4–16; pp. 7–17; pp. 11–18; pp. 18–20; p. 4
A21: P19 | B21: PS065 | C21: Making Smart Contracts Smarter | D21: ED4 | E21: — | F21: RT2 | G21: RT1 | H21: CT7 | I21: CT2 | J21: LC4 | K21: — | L21: EV5 | M21: EV4 | N21: Applicable | O21: EM4 | P21: 4 | Q21: 5 | R21: Component/Subsystem | S21: AI-assisted second-pass evidence verification reproduces the finalized S3 coding. This is not blind independent human Reviewer-2 coding; human R2 sign-off is pending. | T21: Abstract; Sec. 1; Secs. 3–5; Sec. 6; Secs. 6–7; Abstract; Sec. 6; Secs. 1, 5–6
A22: P20 | B22: PS066 | C22: Securify: Practical Security Analysis of Smart Contracts | D22: ED4 | E22: — | F22: RT3 | G22: RT2; RT1 | H22: CT7 | I22: CT2 | J22: LC4 | K22: — | L22: EV9 | M22: EV5 | N22: Applicable | O22: EM6 | P22: 7 | Q22: 8 | R22: Component/Subsystem | S22: AI-assisted second-pass evidence verification reproduces the finalized S3 coding. This is not blind independent human Reviewer-2 coding; human R2 sign-off is pending. | T22: Abstract; Sec. 1; Secs. 3–6; Sec. 7; Secs. 1 and 7; Sec. 1; Abstract; Secs. 1 and 7
A23: P21 | B23: PS067 | C23: ZEUS: Analyzing Safety of Smart Contracts | D23: ED4 | E23: — | F23: RT2 | G23: RT1 | H23: CT7 | I23: CT2 | J23: LC4 | K23: — | L23: EV5 | M23: EV4 | N23: Applicable | O23: EM4 | P23: 4 | Q23: 5 | R23: Component/Subsystem | S23: AI-assisted second-pass evidence verification reproduces the finalized S3 coding. This is not blind independent human Reviewer-2 coding; human R2 sign-off is pending. | T23: Abstract; Sec. I; Secs. III–V; Sec. VI; Sec. VI-A; Abstract; Sec. VI; Secs. I and VI; full text
A24: P22 | B24: PS082 | C24: Correct-by-Design Interacting Smart Contracts and a Systematic Approach for Verifying ERC20 and ERC721 Contracts With VeriSolid | D24: ED4 | E24: ED3 | F24: RT2 | G24: RT1 | H24: CT2 | I24: CT7; CT10 | J24: LC4 | K24: LC2; LC3 | L24: EV5 | M24: EV4 | N24: Applicable | O24: EM4 | P24: 4 | Q24: 5 | R24: Component/Subsystem | S24: AI-assisted second-pass evidence verification reproduces the finalized S3 coding. This is not blind independent human Reviewer-2 coding; human R2 sign-off is pending. | T24: PDF pp. 1–2; PDF pp. 2–9; PDF pp. 2–10; PDF pp. 13–16; PDF pp. 13–17; PDF pp. 2 and 18
A25: P23 | B25: PS087 | C25: Smart Contract Vulnerability Detection Techniques for Hyperledger Fabric | D25: ED4 | E25: — | F25: RT2 | G25: RT1 | H25: CT7 | I25: — | J25: LC4 | K25: — | L25: EV2 | M25: — | N25: Applicable | O25: EM1 | P25: 2 | Q25: 3 | R25: Component/Subsystem | S25: AI-assisted second-pass evidence verification reproduces the finalized S3 coding. This is not blind independent human Reviewer-2 coding; human R2 sign-off is pending. | T25: PDF pp. 1–2; PDF pp. 2–5; PDF pp. 5–6; PDF p. 6; PDF pp. 6–7; PDF pp. 2–6
A26: P24 | B26: PS089 | C26: SGDL: Smart Contract Vulnerability Generation via Deep Learning | D26: ED4 | E26: — | F26: RT2 | G26: RT1 | H26: CT2 | I26: CT7 | J26: LC4 | K26: — | L26: EV5 | M26: EV4 | N26: Applicable | O26: EM4 | P26: 4 | Q26: 5 | R26: Component/Subsystem | S26: AI-assisted second-pass evidence verification reproduces the finalized S3 coding. This is not blind independent human Reviewer-2 coding; human R2 sign-off is pending. | T26: PDF pp. 1–2; PDF pp. 2–13; PDF pp. 7, 13–19; PDF pp. 7 and 13–19; PDF pp. 13–19; PDF pp. 14–20; PDF pp. 16–20; PDF pp. 13 and 22
A27: P25 | B27: PS093 | C27: VULSEYE: Detect Smart Contract Vulnerabilities via Stateful Directed Graybox Fuzzing | D27: ED4 | E27: — | F27: RT2 | G27: RT1 | H27: CT7 | I27: CT2 | J27: LC4 | K27: — | L27: EV5 | M27: EV4 | N27: Applicable | O27: EM4 | P27: 4 | Q27: 5 | R27: Component/Subsystem | S27: AI-assisted second-pass evidence verification reproduces the finalized S3 coding. This is not blind independent human Reviewer-2 coding; human R2 sign-off is pending. | T27: PDF pp. 1–4; PDF pp. 4–8; PDF pp. 6–9; PDF pp. 9–12; PDF pp. 11–13; PDF p. 2

Sheet Screening_Title_Abstract
A1: Title-and-Abstract Screening Reliability
A3: Record ID | B3: Reviewer 1 | C3: Reviewer 2 | D3: Agreement? | F3: Metric | G3: Value
A4: Not supplied 01 | B4: Not supplied | C4: Not supplied | D4: =IF(OR(B4="Not supplied",C4="Not supplied"),"Not evaluable",IF(B4=C4,"Yes","No")) -> Not evaluable | F4: Paired N | G4: =SUM(G5:G8) -> 0
A5: Not supplied 02 | B5: Not supplied | C5: Not supplied | D5: =IF(OR(B5="Not supplied",C5="Not supplied"),"Not evaluable",IF(B5=C5,"Yes","No")) -> Not evaluable | F5: Both Include | G5: =COUNTIFS(B4:B103,"Include",C4:C103,"Include") -> 0
A6: Not supplied 03 | B6: Not supplied | C6: Not supplied | D6: =IF(OR(B6="Not supplied",C6="Not supplied"),"Not evaluable",IF(B6=C6,"Yes","No")) -> Not evaluable | F6: R1 Include/R2 Exclude | G6: =COUNTIFS(B4:B103,"Include",C4:C103,"Exclude") -> 0
A7: Not supplied 04 | B7: Not supplied | C7: Not supplied | D7: =IF(OR(B7="Not supplied",C7="Not supplied"),"Not evaluable",IF(B7=C7,"Yes","No")) -> Not evaluable | F7: R1 Exclude/R2 Include | G7: =COUNTIFS(B4:B103,"Exclude",C4:C103,"Include") -> 0
A8: Not supplied 05 | B8: Not supplied | C8: Not supplied | D8: =IF(OR(B8="Not supplied",C8="Not supplied"),"Not evaluable",IF(B8=C8,"Yes","No")) -> Not evaluable | F8: Both Exclude | G8: =COUNTIFS(B4:B103,"Exclude",C4:C103,"Exclude") -> 0
A9: Not supplied 06 | B9: Not supplied | C9: Not supplied | D9: =IF(OR(B9="Not supplied",C9="Not supplied"),"Not evaluable",IF(B9=C9,"Yes","No")) -> Not evaluable | F9: Raw agreement | G9: =IF(G4=0,"Not calculable",(G5+G8)/G4) -> Not calculable
A10: Not supplied 07 | B10: Not supplied | C10: Not supplied | D10: =IF(OR(B10="Not supplied",C10="Not supplied"),"Not evaluable",IF(B10=C10,"Yes","No")) -> Not evaluable | F10: Expected agreement | G10: =IF(G4=0,"Not calculable",((G5+G6)/G4)*((G5+G7)/G4)+((G7+G8)/G4)*((G6+G8)/G4)) -> Not calculable
A11: Not supplied 08 | B11: Not supplied | C11: Not supplied | D11: =IF(OR(B11="Not supplied",C11="Not supplied"),"Not evaluable",IF(B11=C11,"Yes","No")) -> Not evaluable | F11: Cohen kappa | G11: =IF(OR(G4=0,G9="Not calculable",G10="Not calculable",G10=1),"Not calculable",(G9-G10)/(1-G10)) -> Not calculable
A12: Not supplied 09 | B12: Not supplied | C12: Not supplied | D12: =IF(OR(B12="Not supplied",C12="Not supplied"),"Not evaluable",IF(B12=C12,"Yes","No")) -> Not evaluable | F12: Raw target | G12: 0.8
A13: Not supplied 10 | B13: Not supplied | C13: Not supplied | D13: =IF(OR(B13="Not supplied",C13="Not supplied"),"Not evaluable",IF(B13=C13,"Yes","No")) -> Not evaluable | F13: Kappa target | G13: 0.7
D14: =IF(OR(B14="Not supplied",C14="Not supplied"),"Not evaluable",IF(B14=C14,"Yes","No")) -> Yes | F14: Status | G14: Pending independent sample
D15: =IF(OR(B15="Not supplied",C15="Not supplied"),"Not evaluable",IF(B15=C15,"Yes","No")) -> Yes
D16: =IF(OR(B16="Not supplied",C16="Not supplied"),"Not evaluable",IF(B16=C16,"Yes","No")) -> Yes
D17: =IF(OR(B17="Not supplied",C17="Not supplied"),"Not evaluable",IF(B17=C17,"Yes","No")) -> Yes
D18: =IF(OR(B18="Not supplied",C18="Not supplied"),"Not evaluable",IF(B18=C18,"Yes","No")) -> Yes
D19: =IF(OR(B19="Not supplied",C19="Not supplied"),"Not evaluable",IF(B19=C19,"Yes","No")) -> Yes
D20: =IF(OR(B20="Not supplied",C20="Not supplied"),"Not evaluable",IF(B20=C20,"Yes","No")) -> Yes
D21: =IF(OR(B21="Not supplied",C21="Not supplied"),"Not evaluable",IF(B21=C21,"Yes","No")) -> Yes
D22: =IF(OR(B22="Not supplied",C22="Not supplied"),"Not evaluable",IF(B22=C22,"Yes","No")) -> Yes
D23: =IF(OR(B23="Not supplied",C23="Not supplied"),"Not evaluable",IF(B23=C23,"Yes","No")) -> Yes
D24: =IF(OR(B24="Not supplied",C24="Not supplied"),"Not evaluable",IF(B24=C24,"Yes","No")) -> Yes
D25: =IF(OR(B25="Not supplied",C25="Not supplied"),"Not evaluable",IF(B25=C25,"Yes","No")) -> Yes
D26: =IF(OR(B26="Not supplied",C26="Not supplied"),"Not evaluable",IF(B26=C26,"Yes","No")) -> Yes
... D35: =IF(OR(B35="Not supplied",C35="Not supplied"),"Not evaluable",IF(B35=C35,"Yes","No")) -> Yes
D36: =IF(OR(B36="",C36=""),"",IF(B36=C36,"Yes","No"))
D37: =IF(OR(B37="",C37=""),"",IF(B37=C37,"Yes","No"))
D38: =IF(OR(B38="",C38=""),"",IF(B38=C38,"Yes","No"))
D39: =IF(OR(B39="",C39=""),"",IF(B39=C39,"Yes","No"))
D40: =IF(OR(B40="",C40=""),"",IF(B40=C40,"Yes","No"))
D41: =IF(OR(B41="",C41=""),"",IF(B41=C41,"Yes","No"))
D42: =IF(OR(B42="",C42=""),"",IF(B42=C42,"Yes","No"))
D43: =IF(OR(B43="",C43=""),"",IF(B43=C43,"Yes","No"))
D44: =IF(OR(B44="",C44=""),"",IF(B44=C44,"Yes","No"))
D45: =IF(OR(B45="",C45=""),"",IF(B45=C45,"Yes","No"))
D46: =IF(OR(B46="",C46=""),"",IF(B46=C46,"Yes","No"))
D47: =IF(OR(B47="",C47=""),"",IF(B47=C47,"Yes","No"))
... D103: =IF(OR(B103="",C103=""),"",IF(B103=C103,"Yes","No"))

Sheet Screening_Full_Text
A1: Full-Text Eligibility Reliability
A3: Record ID | B3: Reviewer 1 | C3: Reviewer 2 | D3: Agreement? | F3: Metric | G3: Value
A4: Not supplied 01 | B4: Not supplied | C4: Not supplied | D4: =IF(OR(B4="Not supplied",C4="Not supplied"),"Not evaluable",IF(B4=C4,"Yes","No")) -> Not evaluable | F4: Paired N | G4: =SUM(G5:G8) -> 0
A5: Not supplied 02 | B5: Not supplied | C5: Not supplied | D5: =IF(OR(B5="Not supplied",C5="Not supplied"),"Not evaluable",IF(B5=C5,"Yes","No")) -> Not evaluable | F5: Both Include | G5: =COUNTIFS(B4:B103,"Include",C4:C103,"Include") -> 0
A6: Not supplied 03 | B6: Not supplied | C6: Not supplied | D6: =IF(OR(B6="Not supplied",C6="Not supplied"),"Not evaluable",IF(B6=C6,"Yes","No")) -> Not evaluable | F6: R1 Include/R2 Exclude | G6: =COUNTIFS(B4:B103,"Include",C4:C103,"Exclude") -> 0
A7: Not supplied 04 | B7: Not supplied | C7: Not supplied | D7: =IF(OR(B7="Not supplied",C7="Not supplied"),"Not evaluable",IF(B7=C7,"Yes","No")) -> Not evaluable | F7: R1 Exclude/R2 Include | G7: =COUNTIFS(B4:B103,"Exclude",C4:C103,"Include") -> 0
A8: Not supplied 05 | B8: Not supplied | C8: Not supplied | D8: =IF(OR(B8="Not supplied",C8="Not supplied"),"Not evaluable",IF(B8=C8,"Yes","No")) -> Not evaluable | F8: Both Exclude | G8: =COUNTIFS(B4:B103,"Exclude",C4:C103,"Exclude") -> 0
A9: Not supplied 06 | B9: Not supplied | C9: Not supplied | D9: =IF(OR(B9="Not supplied",C9="Not supplied"),"Not evaluable",IF(B9=C9,"Yes","No")) -> Not evaluable | F9: Raw agreement | G9: =IF(G4=0,"Not calculable",(G5+G8)/G4) -> Not calculable
A10: Not supplied 07 | B10: Not supplied | C10: Not supplied | D10: =IF(OR(B10="Not supplied",C10="Not supplied"),"Not evaluable",IF(B10=C10,"Yes","No")) -> Not evaluable | F10: Expected agreement | G10: =IF(G4=0,"Not calculable",((G5+G6)/G4)*((G5+G7)/G4)+((G7+G8)/G4)*((G6+G8)/G4)) -> Not calculable
A11: Not supplied 08 | B11: Not supplied | C11: Not supplied | D11: =IF(OR(B11="Not supplied",C11="Not supplied"),"Not evaluable",IF(B11=C11,"Yes","No")) -> Not evaluable | F11: Cohen kappa | G11: =IF(OR(G4=0,G9="Not calculable",G10="Not calculable",G10=1),"Not calculable",(G9-G10)/(1-G10)) -> Not calculable
A12: Not supplied 09 | B12: Not supplied | C12: Not supplied | D12: =IF(OR(B12="Not supplied",C12="Not supplied"),"Not evaluable",IF(B12=C12,"Yes","No")) -> Not evaluable | F12: Raw target | G12: 0.8
A13: Not supplied 10 | B13: Not supplied | C13: Not supplied | D13: =IF(OR(B13="Not supplied",C13="Not supplied"),"Not evaluable",IF(B13=C13,"Yes","No")) -> Not evaluable | F13: Kappa target | G13: 0.7
D14: =IF(OR(B14="Not supplied",C14="Not supplied"),"Not evaluable",IF(B14=C14,"Yes","No")) -> Yes | F14: Status | G14: Pending independent sample
D15: =IF(OR(B15="Not supplied",C15="Not supplied"),"Not evaluable",IF(B15=C15,"Yes","No")) -> Yes
D16: =IF(OR(B16="Not supplied",C16="Not supplied"),"Not evaluable",IF(B16=C16,"Yes","No")) -> Yes
D17: =IF(OR(B17="Not supplied",C17="Not supplied"),"Not evaluable",IF(B17=C17,"Yes","No")) -> Yes
D18: =IF(OR(B18="Not supplied",C18="Not supplied"),"Not evaluable",IF(B18=C18,"Yes","No")) -> Yes
D19: =IF(OR(B19="Not supplied",C19="Not supplied"),"Not evaluable",IF(B19=C19,"Yes","No")) -> Yes
D20: =IF(OR(B20="Not supplied",C20="Not supplied"),"Not evaluable",IF(B20=C20,"Yes","No")) -> Yes
D21: =IF(OR(B21="Not supplied",C21="Not supplied"),"Not evaluable",IF(B21=C21,"Yes","No")) -> Yes
D22: =IF(OR(B22="Not supplied",C22="Not supplied"),"Not evaluable",IF(B22=C22,"Yes","No")) -> Yes
D23: =IF(OR(B23="Not supplied",C23="Not supplied"),"Not evaluable",IF(B23=C23,"Yes","No")) -> Yes
D24: =IF(OR(B24="Not supplied",C24="Not supplied"),"Not evaluable",IF(B24=C24,"Yes","No")) -> Yes
D25: =IF(OR(B25="Not supplied",C25="Not supplied"),"Not evaluable",IF(B25=C25,"Yes","No")) -> Yes
D26: =IF(OR(B26="Not supplied",C26="Not supplied"),"Not evaluable",IF(B26=C26,"Yes","No")) -> Yes
... D35: =IF(OR(B35="Not supplied",C35="Not supplied"),"Not evaluable",IF(B35=C35,"Yes","No")) -> Yes
D36: =IF(OR(B36="",C36=""),"",IF(B36=C36,"Yes","No"))
D37: =IF(OR(B37="",C37=""),"",IF(B37=C37,"Yes","No"))
D38: =IF(OR(B38="",C38=""),"",IF(B38=C38,"Yes","No"))
D39: =IF(OR(B39="",C39=""),"",IF(B39=C39,"Yes","No"))
D40: =IF(OR(B40="",C40=""),"",IF(B40=C40,"Yes","No"))
D41: =IF(OR(B41="",C41=""),"",IF(B41=C41,"Yes","No"))
D42: =IF(OR(B42="",C42=""),"",IF(B42=C42,"Yes","No"))
D43: =IF(OR(B43="",C43=""),"",IF(B43=C43,"Yes","No"))
D44: =IF(OR(B44="",C44=""),"",IF(B44=C44,"Yes","No"))
D45: =IF(OR(B45="",C45=""),"",IF(B45=C45,"Yes","No"))
D46: =IF(OR(B46="",C46=""),"",IF(B46=C46,"Yes","No"))
D47: =IF(OR(B47="",C47=""),"",IF(B47=C47,"Yes","No"))
... D103: =IF(OR(B103="",C103=""),"",IF(B103=C103,"Yes","No"))

Sheet MultiLabel_Reliability
A1: Multi-Label Reliability — Per-Label Binary Kappa and Jaccard Procedure
A3: Facet | B3: Label | C3: N | D3: 1/1 | E3: 1/0 | F3: 0/1 | G3: 0/0 | H3: Raw agreement | I3: Expected agreement | J3: Binary kappa | K3: Target | L3: Status
A4: ED | B4: ED1 | C4: 25 | D4: 6 | E4: 0 | F4: 0 | G4: 19 | H4: =IF(C4=0,"",(D4+G4)/C4) -> 1 | I4: =IF(C4=0,"",((D4+E4)/C4)*((D4+F4)/C4)+((F4+G4)/C4)*((E4+G4)/C4)) -> 0.6352 | J4: =IF(OR(H4="",I4="",I4=1),"",(H4-I4)/(1-I4)) -> 1 | K4: ≥0.70 | L4: =IF(J4="","Pending",IF(J4>=0.7,"PASS","REVIEW")) -> PASS
A5: ED | B5: ED2 | C5: 25 | D5: 6 | E5: 0 | F5: 0 | G5: 19 | H5: =IF(C5=0,"",(D5+G5)/C5) -> 1 | I5: =IF(C5=0,"",((D5+E5)/C5)*((D5+F5)/C5)+((F5+G5)/C5)*((E5+G5)/C5)) -> 0.6352 | J5: =IF(OR(H5="",I5="",I5=1),"",(H5-I5)/(1-I5)) -> 1 | K5: ≥0.70 | L5: =IF(J5="","Pending",IF(J5>=0.7,"PASS","REVIEW")) -> PASS
A6: ED | B6: ED3 | C6: 25 | D6: 7 | E6: 0 | F6: 0 | G6: 18 | H6: =IF(C6=0,"",(D6+G6)/C6) -> 1 | I6: =IF(C6=0,"",((D6+E6)/C6)*((D6+F6)/C6)+((F6+G6)/C6)*((E6+G6)/C6)) -> 0.5968 | J6: =IF(OR(H6="",I6="",I6=1),"",(H6-I6)/(1-I6)) -> 1 | K6: ≥0.70 | L6: =IF(J6="","Pending",IF(J6>=0.7,"PASS","REVIEW")) -> PASS
A7: ED | B7: ED4 | C7: 25 | D7: 7 | E7: 0 | F7: 0 | G7: 18 | H7: =IF(C7=0,"",(D7+G7)/C7) -> 1 | I7: =IF(C7=0,"",((D7+E7)/C7)*((D7+F7)/C7)+((F7+G7)/C7)*((E7+G7)/C7)) -> 0.5968 | J7: =IF(OR(H7="",I7="",I7=1),"",(H7-I7)/(1-I7)) -> 1 | K7: ≥0.70 | L7: =IF(J7="","Pending",IF(J7>=0.7,"PASS","REVIEW")) -> PASS
A8: RT | B8: RT1 | C8: 25 | D8: 22 | E8: 0 | F8: 0 | G8: 3 | H8: =IF(C8=0,"",(D8+G8)/C8) -> 1 | I8: =IF(C8=0,"",((D8+E8)/C8)*((D8+F8)/C8)+((F8+G8)/C8)*((E8+G8)/C8)) -> 0.7888 | J8: =IF(OR(H8="",I8="",I8=1),"",(H8-I8)/(1-I8)) -> 1 | K8: ≥0.70 | L8: =IF(J8="","Pending",IF(J8>=0.7,"PASS","REVIEW")) -> PASS
A9: RT | B9: RT2 | C9: 25 | D9: 21 | E9: 0 | F9: 0 | G9: 4 | H9: =IF(C9=0,"",(D9+G9)/C9) -> 1 | I9: =IF(C9=0,"",((D9+E9)/C9)*((D9+F9)/C9)+((F9+G9)/C9)*((E9+G9)/C9)) -> 0.7312 | J9: =IF(OR(H9="",I9="",I9=1),"",(H9-I9)/(1-I9)) -> 1 | K9: ≥0.70 | L9: =IF(J9="","Pending",IF(J9>=0.7,"PASS","REVIEW")) -> PASS
A10: RT | B10: RT3 | C10: 25 | D10: 6 | E10: 0 | F10: 0 | G10: 19 | H10: =IF(C10=0,"",(D10+G10)/C10) -> 1 | I10: =IF(C10=0,"",((D10+E10)/C10)*((D10+F10)/C10)+((F10+G10)/C10)*((E10+G10)/C10)) -> 0.6352 | J10: =IF(OR(H10="",I10="",I10=1),"",(H10-I10)/(1-I10)) -> 1 | K10: ≥0.70 | L10: =IF(J10="","Pending",IF(J10>=0.7,"PASS","REVIEW")) -> PASS
A11: RT | B11: RT4 | C11: 25 | D11: 0 | E11: 0 | F11: 0 | G11: 25 | H11: =IF(C11=0,"",(D11+G11)/C11) -> 1 | I11: =IF(C11=0,"",((D11+E11)/C11)*((D11+F11)/C11)+((F11+G11)/C11)*((E11+G11)/C11)) -> 1 | J11: =IF(OR(H11="",I11="",I11=1),"",(H11-I11)/(1-I11)) | K11: ≥0.70 | L11: =IF(J11="","Pending",IF(J11>=0.7,"PASS","REVIEW")) -> Pending
A12: RT | B12: RT5 | C12: 25 | D12: 0 | E12: 0 | F12: 0 | G12: 25 | H12: =IF(C12=0,"",(D12+G12)/C12) -> 1 | I12: =IF(C12=0,"",((D12+E12)/C12)*((D12+F12)/C12)+((F12+G12)/C12)*((E12+G12)/C12)) -> 1 | J12: =IF(OR(H12="",I12="",I12=1),"",(H12-I12)/(1-I12)) | K12: ≥0.70 | L12: =IF(J12="","Pending",IF(J12>=0.7,"PASS","REVIEW")) -> Pending
A13: RT | B13: RT6 | C13: 25 | D13: 0 | E13: 0 | F13: 0 | G13: 25 | H13: =IF(C13=0,"",(D13+G13)/C13) -> 1 | I13: =IF(C13=0,"",((D13+E13)/C13)*((D13+F13)/C13)+((F13+G13)/C13)*((E13+G13)/C13)) -> 1 | J13: =IF(OR(H13="",I13="",I13=1),"",(H13-I13)/(1-I13)) | K13: ≥0.70 | L13: =IF(J13="","Pending",IF(J13>=0.7,"PASS","REVIEW")) -> Pending
A14: CT | B14: CT1 | C14: 25 | D14: 2 | E14: 0 | F14: 0 | G14: 23 | H14: =IF(C14=0,"",(D14+G14)/C14) -> 1 | I14: =IF(C14=0,"",((D14+E14)/C14)*((D14+F14)/C14)+((F14+G14)/C14)*((E14+G14)/C14)) -> 0.8528 | J14: =IF(OR(H14="",I14="",I14=1),"",(H14-I14)/(1-I14)) -> 1 | K14: ≥0.70 | L14: =IF(J14="","Pending",IF(J14>=0.7,"PASS","REVIEW")) -> PASS
A15: CT | B15: CT2 | C15: 25 | D15: 8 | E15: 0 | F15: 0 | G15: 17 | H15: =IF(C15=0,"",(D15+G15)/C15) -> 1 | I15: =IF(C15=0,"",((D15+E15)/C15)*((D15+F15)/C15)+((F15+G15)/C15)*((E15+G15)/C15)) -> 0.5648 | J15: =IF(OR(H15="",I15="",I15=1),"",(H15-I15)/(1-I15)) -> 1 | K15: ≥0.70 | L15: =IF(J15="","Pending",IF(J15>=0.7,"PASS","REVIEW")) -> PASS
... A45: EV | B45: EV11 | C45: 25 | D45: 0 | E45: 0 | F45: 0 | G45: 25 | H45: =IF(C45=0,"",(D45+G45)/C45) -> 1 | I45: =IF(C45=0,"",((D45+E45)/C45)*((D45+F45)/C45)+((F45+G45)/C45)*((E45+G45)/C45)) -> 1 | J45: =IF(OR(H45="",I45="",I45=1),"",(H45-I45)/(1-I45)) | K45: ≥0.70 | L45: =IF(J45="","Pending",IF(J45>=0.7,"PASS","REVIEW")) -> Pending
J46: =IF(C46=0,"Not calculable",IF(I46=1,"NA - zero variance",(H46-I46)/(1-I46))) -> Not calculable | L46: Verification-only; not formal IRR
J47: =IF(C47=0,"Not calculable",IF(I47=1,"NA - zero variance",(H47-I47)/(1-I47))) -> Not calculable | L47: Verification-only; not formal IRR
A49: Jaccard reporting | B49: Formula | C49: Interpretation | D49: Recommendation
A50: Per-study/facet | B50: intersection / union | C50: 0=no shared labels; 1=identical non-empty sets | D50: Report distribution or mean/median by facet
A51: Both sets empty | B51: NA | C51: No substantive label was assigned by either reviewer | D51: Do not count this as perfect agreement
A52: Use with kappa | B52: Complementary | C52: Jaccard captures set overlap; per-label kappa adjusts for chance | D52: Report both for multi-label variables

Sheet Ordinal_Reliability
A1: Ordinal Reliability — Evidence Maturity and Reviewer-Inferred TRL
A2: Variable | B2: Categories | C2: Agreement statistic | D2: Primary calculation unit | E2: Raw agreement | F2: Target | G2: Decision rule | H2: Reporting note
A3: Evidence maturity | B3: EM0–EM7 | C3: Weighted Cohen kappa | D3: One EM level per applicable study | E3: 1 | F3: ≥0.70 | G3: Compare only paired applicable EM codes | H3: Observed verification-only exact agreement = 1.00 across 23 EM-applicable pilot studies; not formal IRR.
A4: Reviewer-inferred TRL lower bound | B4: 1–9 | C4: Weighted Cohen kappa | D4: Lower bound of reviewer range | E4: 1 | F4: ≥0.70 | G4: Compare lower bounds separately | H4: Observed verification-only exact agreement = 1.00 across 23 paired TRL lower bounds; not formal IRR.
A5: Reviewer-inferred TRL upper bound | B5: 1–9 | C5: Weighted Cohen kappa | D5: Upper bound of reviewer range | E5: 1 | F5: ≥0.70 | G5: Compare upper bounds separately | H5: Observed verification-only exact agreement = 1.00 across 23 paired TRL upper bounds; not formal IRR.
A7: Weighting | B7: Weight formula | C7: Use | D7: Status
A8: Linear | B8: w_ij = 1 - |i-j|/(k-1) | C8: Penalizes disagreement in direct proportion to category distance | D8: Available
A9: Quadratic | B9: w_ij = 1 - (|i-j|/(k-1))^2 | C9: Penalizes large category disagreements more strongly | D9: Available
A11: Weighted kappa equation | B11: Observed weighted agreement | C11: Expected weighted agreement | D11: Pre-specification rule
A12: κw = (P_o,w - P_e,w) / (1 - P_e,w) | B12: P_o,w = Σ_i Σ_j w_ij p_ij | C12: P_e,w = Σ_i Σ_j w_ij p_i. p_.j | D12: Choose and state the primary weighting before seeing the final reliability results.

Sheet Codebook_Refinement_Log
A1: Pilot-Codebook Refinement Log
A3: Round | B3: Date | C3: Study ID(s) | D3: Facet/variable | E3: Ambiguous case / disagreement | F3: Original rule | G3: Revised rule / clarification | H3: Change type | I3: Reason | J3: Earlier studies affected? | K3: Recoding completed? | L3: Protocol-deviation ref
A4: Status | B4: Not independently documented | C4: P01–P25 | D4: All S3 facets / EM / TRL | E4: No independently documented post-pilot disagreement/refinement event was supplied in the current materials. | F4: Current S3 codebook and decision rules | G4: No new rule change is asserted in S5; use the finalized S3 rules already applied to the pilot recode. | H4: Administrative status record | I4: Prevents a blank log from being misread as evidence of an undocumented refinement event. | J4: No | K4: R1 final recode available; independent human R2 recoding pending | L4: None

Sheet Adjudication_Log
A1: Disagreement and Third-Reviewer Adjudication Log
A3: Round | B3: Study ID | C3: Variable | D3: Reviewer 1 code | E3: Reviewer 2 code | F3: R1 rationale | G3: R2 rationale | H3: Consensus reached? | I3: Consensus code | J3: Third reviewer? | K3: Third-reviewer decision | L3: Resolution note
A4: Status | B4: P01–P25 | C4: All pilot variables | D4: Finalized S3 R1 codes | E4: AI-assisted evidence-verification values; not independent human R2 codes | F4: R1 values are grounded in the finalized S3 classification. | G4: Verification pass reproduced the finalized values; this cannot substitute for independent coding. | H4: Not formally evaluable | I4: Pending independent human R2 | J4: Not triggered | K4: NA | L4: No formal disagreement/adjudication result is claimed until independent human Reviewer-2 coding is completed.

Sheet Reliability_Summary
A1: Inter-Rater Reliability Reporting Summary
A2: Variable | B2: Method | C2: Sample / N | D2: Raw agreement | E2: Kappa / Jaccard | F2: Target | G2: Status | H2: Additional round? | I2: Final manuscript value | J2: Notes
A3: Title/abstract screening | B3: Binary Cohen kappa | C3: 0 | D3: Not calculable | E3: Not calculable | F3: Raw ≥0.80; κ ≥0.70 | G3: Pending independent sample | H3: Yes — obtain independent screening sample | I3: Pending | J3: No title/abstract reliability sample containing Include + Exclude decisions was supplied.
A4: Full-text eligibility | B4: Binary Cohen kappa | C4: 0 | D4: Not calculable | E4: Not calculable | F4: Raw ≥0.80; κ ≥0.70 | G4: Pending independent sample | H4: Yes — obtain independent screening sample | I4: Pending | J4: No full-text reliability sample containing Include + Exclude decisions was supplied.
A5: Engineering domain | B5: Primary nominal kappa + per-label kappa + Jaccard | C5: 25 | D5: 1.00 | E5: κ(primary)=1.00; Jaccard=1.00 (verification-only) | F5: Raw ≥0.80; κ ≥0.70 | G5: Verification-only — NOT formal IRR | H5: Yes — independent human R2 required | I5: Pending independent human R2 | J5: Observed perfect agreement reflects verification of finalized coding, not independent reviewer coding.
A6: Research type | B6: Primary nominal kappa + per-label kappa + Jaccard | C6: 25 | D6: 1.00 | E6: κ(primary)=1.00; Jaccard=1.00 (verification-only) | F6: Raw ≥0.80; κ ≥0.70 | G6: Verification-only — NOT formal IRR | H6: Yes — independent human R2 required | I6: Pending independent human R2 | J6: Observed perfect agreement reflects verification of finalized coding, not independent reviewer coding.
A7: Contribution type | B7: Primary nominal kappa + per-label kappa + Jaccard | C7: 25 | D7: 1.00 | E7: κ(primary)=1.00; Jaccard=1.00 (verification-only) | F7: Raw ≥0.80; κ ≥0.70 | G7: Verification-only — NOT formal IRR | H7: Yes — independent human R2 required | I7: Pending independent human R2 | J7: Observed perfect agreement reflects verification of finalized coding, not independent reviewer coding.
